# Java 异常

[TOC]

在异常处理理论中，有两种基本模型：

- **终止模型**（termination）：假设错误是如此严重，以至于无法返回到异常发生的地方
- **恢复模型**（resumption）：异常处理程序有望通过某些工作来修正这种情况，然后重新尝试出现问题的方法

Java支持**终止模型**（termination）。如果想在Java中获得类似恢复模型的行为，那么：

1. 当遇到错误时不要抛出异常，而是要调用某个能修复这个问题的方法
2. 把我们的`try`块放在一个`while`循环中，不断地重新进入这个`try`块，直到结果令人满意。

检查型异常实际上是 Java 的发明，然而，这只是一次尝试，之后的编程语言并没有采用这样的做法。

## Exception

![img](./assets/exception-hierarchy.png)

异常语法的注意点：

1. 在重写一个方法时，只能抛出该方法的基类版本中说明的异常
2. 当一个异常被抛出时，异常处理系统会按照处理程序的编写顺序来寻找“最近的”那个。当找到一个匹配的处理程序时，它会认为该异常得到了处理，从而不再进行进一步的搜索。因此，可以将基类异常对应的`catch`子句放在最前面，从而屏蔽掉子类的异常。



有时我们会捕捉一个异常并抛出另一个，但仍然保留原始异常的信息，这称为**异常链**。异常链的构造有两种方式：

1. 构造函数 `Throwable(String message, Throwable cause)`

   ~~~java
   Throwable t = new Throwable("an error message", new Exception("cause exception"));
   ~~~

2. initCause() 方法

   ~~~java
   Throwable t = new Throwable("an error message");
   t.initCause(new Exception("cause exception"));
   ~~~

   `initCause()` 方法只能被调用一次。如果尝试第二次调用此方法，它会抛出一个 `IllegalStateException` 。

异常的输出：

~~~java
try {
    // 抛出一个异常，传入详细的异常信息以及原因
    throw new Exception("An error occurred", new NullPointerException("null reference"));
} catch (Exception e) {
    System.out.println(e.getMessage());  // 返回 String，输出 "An error occurred"
    
    System.out.println(e.toString());    // 返回 String，输出 "java.lang.Exception: An error occurred"
    
    System.out.println(e.getCause());    // 返回 Throwable 类型，输出 "java.lang.NullPointerException: null reference"
    
    for (StackTraceElement element : e.getStackTrace()) {
        System.out.println(element);     // 输出异常发生时的堆栈轨迹
    }
}
~~~



## try - with - resource

我们先看一个处理构造器异常的错误例子：

~~~java
BufferedReader in = null;
try {
    in = new BufferedReader(new FileReader(filename));
} catch (Exception e) {
    
} finally {
    in.close()；
}

~~~

如果构造器抛出了异常，那么表明对象处于不安全的状态。但是这里不管对象构造成功与否，finally 总会调用对象的 close 方法。这显然是不合理的。正确的做法是使用嵌套的 try 块：

~~~java
try {
    BufferReader in = new BufferedReader(new FileReader(filename));
    try {
        
    } catch (Excpetion e) {
        //处理其他异常
    } finally {
        in.close();
    }
} catch (Exception e) {
    //处理构造器抛出的异常
}
~~~



再给出一个更加常见的例子：

~~~java
class NeedsCleanup {			
    // 假设构造不会失败
    public void dispose() {}
}

class ConstructionException extends Exception {}

class NeedsCleanup2 {
    // 假设构造可能失败
    NeedsCleanup2() throws Exception {}
    public void clean() {}
}

public class CleanupIdiom {
    public static void main(String[] args) {
        
        NeedsCleanup nc1 = new NeedsCleanup();		//[1]
        NeedsCleanup nc2 = new NeedsCleanup();
        
        try {
            //其他代码
        } catch (Exception e) {
            
        } finally {
            nc2.dispose();
            nc1.dispose();						//[3]
        }
        
        try {
            NeedsCleanup2 nc3 = new NeedsCleanup2();
            try {
                NeedsCleanup2 nc4 = new NeedsCleanup2();	//[2]
                try {
                    //其他代码
                } catch (Exception e) {
                    
                } finally {
                    nc4.clean();
                }
            } catch (ConstructionException e) {
                //处理nc4的构造异常
            }
            finally {
                nc3.clean(); 
            }
        } catch (ConstructionException e) {
            //处理nc3的构造异常
        }
    }
}
~~~

总结上述惯例用法为：

1. 对于每个需要清理的类，在构造完后立即跟着 try-finally 语句

2. 对于在构造时不会抛出异常的类，它们放在一起。反之，需要嵌套 try 块。

3. 按照相反的构造顺序，执行清理工作




这种处理构造器异常的模板代码还有一种简化形式：

~~~java
InputStream in = null;
try {
    in = new FileInputStream(new File(""));
    //其他代码
} catch (Exception e) {
    //其他异常
} catch (ConstructionException e) {
    //构造器异常
} finally {
    if (in != null) {
        //对象已成功构造
        try {
            in.clean();
        } catch (Exception e) {
            
        }
    }
}
~~~



但编写起来还是有点繁琐，为此 Java 7 引入了 try - with - resources 语法

~~~java
try (
    InputStream in = new FileInputStream(new File(""));
    PrintWriter outfile = new PrintWriter("");
) {
    
} catch (Exception e) {
    
}
~~~

- try 括号中的内容称为**资源说明头（resource specification header）**
- 可以在资源说明头中定义多个对象
- 每个对象必须实现`java.lang.AutoCloseable`接口。该接口只有一个方法`void close()`。



try - with - resource 的顺序问题：

1. close() 方法先于 finally 与 catch 执行
2. 如果在执行某个 close() 方法时抛出异常，那么不影响其他 close() 方法的执行
4. 如果在某个对象创建时抛出异常，那么就按照与创建顺序的逆序，来**执行该对象之前**（不包括该对象）的 close() 方法。

### 异常抑制

当对外部资源进行处理时，如果遭遇了异常A，且在随后的关闭外部资源过程中，又遭遇了异常B，那么你 catch 到的将会是对外部资源进行处理时遭遇的异常A。关闭资源时遭遇的异常 B 将被抑制，但不是丢弃，通过异常的 getSuppressed 方法，可以提取出被抑制的异常。

## finally 的行为

当控制流从 try/catch 块退出后，总会执行 finally 块

- 这里的退出是指 return、throw 等控制语句
- finally 执行时机是控制流退出**后**，例如执行完 return 语句后

~~~java
// 返回 1
int foo() {
    int j = 1;
    try {
        return j;
    } finally {
        j = 10;
    }
}

// 返回 10
int foo() {
    int j = 1;
    try {
        return j;
    } finally {
        j = 10;
        return j;
    }
}
~~~

